<?xml version="1.0" encoding="UTF-8"?>
<testng-results skipped="6" failed="2" ignored="0" total="16" passed="8">
  <reporter-output>
  </reporter-output>
  <suite name="FREE CRM Application Test Automation Test Suite" duration-ms="71168" started-at="2019-05-04T15:27:55Z" finished-at="2019-05-04T15:29:07Z">
    <groups>
    </groups>
    <test name="Free CRM App Test Cases" duration-ms="71168" started-at="2019-05-04T15:27:55Z" finished-at="2019-05-04T15:29:07Z">
      <class name="com.crm.qa.testcases.HomePageTest">
        <test-method status="PASS" signature="setUp()[pri:0, instance:com.crm.qa.testcases.HomePageTest@2758fe70]" name="setUp" is-config="true" duration-ms="8533" started-at="2019-05-04T20:58:04Z" finished-at="2019-05-04T20:58:13Z">
          <reporter-output>
          </reporter-output>
        </test-method> <!-- setUp -->
        <test-method status="PASS" signature="homePageSuccessTest()[pri:1, instance:com.crm.qa.testcases.HomePageTest@2758fe70]" name="homePageSuccessTest" duration-ms="38" started-at="2019-05-04T20:58:13Z" finished-at="2019-05-04T20:58:13Z">
          <reporter-output>
          </reporter-output>
        </test-method> <!-- homePageSuccessTest -->
        <test-method status="PASS" signature="tearDown()[pri:0, instance:com.crm.qa.testcases.HomePageTest@2758fe70]" name="tearDown" is-config="true" duration-ms="710" started-at="2019-05-04T20:58:13Z" finished-at="2019-05-04T20:58:14Z">
          <reporter-output>
          </reporter-output>
        </test-method> <!-- tearDown -->
        <test-method status="PASS" signature="setUp()[pri:0, instance:com.crm.qa.testcases.HomePageTest@2758fe70]" name="setUp" is-config="true" duration-ms="7950" started-at="2019-05-04T20:58:22Z" finished-at="2019-05-04T20:58:30Z">
          <reporter-output>
          </reporter-output>
        </test-method> <!-- setUp -->
        <test-method status="PASS" signature="logoutTest()[pri:2, instance:com.crm.qa.testcases.HomePageTest@2758fe70]" name="logoutTest" duration-ms="673" started-at="2019-05-04T20:58:30Z" finished-at="2019-05-04T20:58:31Z">
          <reporter-output>
          </reporter-output>
        </test-method> <!-- logoutTest -->
        <test-method status="PASS" signature="tearDown()[pri:0, instance:com.crm.qa.testcases.HomePageTest@2758fe70]" name="tearDown" is-config="true" duration-ms="682" started-at="2019-05-04T20:58:31Z" finished-at="2019-05-04T20:58:32Z">
          <reporter-output>
          </reporter-output>
        </test-method> <!-- tearDown -->
      </class> <!-- com.crm.qa.testcases.HomePageTest -->
      <class name="com.crm.qa.testcases.LoginPageTest">
        <test-method status="PASS" signature="setUp()[pri:0, instance:com.crm.qa.testcases.LoginPageTest@627551fb]" name="setUp" is-config="true" duration-ms="8071" started-at="2019-05-04T20:57:55Z" finished-at="2019-05-04T20:58:04Z">
          <reporter-output>
          </reporter-output>
        </test-method> <!-- setUp -->
        <test-method status="PASS" signature="validateLoginPage()[pri:1, instance:com.crm.qa.testcases.LoginPageTest@627551fb]" name="validateLoginPage" duration-ms="62" started-at="2019-05-04T20:58:04Z" finished-at="2019-05-04T20:58:04Z">
          <reporter-output>
          </reporter-output>
        </test-method> <!-- validateLoginPage -->
        <test-method status="PASS" signature="tearDown()[pri:0, instance:com.crm.qa.testcases.LoginPageTest@627551fb]" name="tearDown" is-config="true" duration-ms="689" started-at="2019-05-04T20:58:04Z" finished-at="2019-05-04T20:58:04Z">
          <reporter-output>
          </reporter-output>
        </test-method> <!-- tearDown -->
        <test-method status="PASS" signature="setUp()[pri:0, instance:com.crm.qa.testcases.LoginPageTest@627551fb]" name="setUp" is-config="true" duration-ms="7129" started-at="2019-05-04T20:58:14Z" finished-at="2019-05-04T20:58:21Z">
          <reporter-output>
          </reporter-output>
        </test-method> <!-- setUp -->
        <test-method status="PASS" signature="loginTest()[pri:2, instance:com.crm.qa.testcases.LoginPageTest@627551fb]" name="loginTest" duration-ms="847" started-at="2019-05-04T20:58:21Z" depends-on-methods="com.crm.qa.testcases.LoginPageTest.validateLoginPage" finished-at="2019-05-04T20:58:22Z">
          <reporter-output>
          </reporter-output>
        </test-method> <!-- loginTest -->
        <test-method status="PASS" signature="tearDown()[pri:0, instance:com.crm.qa.testcases.LoginPageTest@627551fb]" name="tearDown" is-config="true" duration-ms="703" started-at="2019-05-04T20:58:22Z" finished-at="2019-05-04T20:58:22Z">
          <reporter-output>
          </reporter-output>
        </test-method> <!-- tearDown -->
        <test-method status="PASS" signature="setUp()[pri:0, instance:com.crm.qa.testcases.LoginPageTest@627551fb]" name="setUp" is-config="true" duration-ms="7120" started-at="2019-05-04T20:58:32Z" finished-at="2019-05-04T20:58:39Z">
          <reporter-output>
          </reporter-output>
        </test-method> <!-- setUp -->
        <test-method status="PASS" signature="validateInvalidLogins(java.lang.String, java.lang.String)[pri:3, instance:com.crm.qa.testcases.LoginPageTest@627551fb]" name="validateInvalidLogins" duration-ms="823" started-at="2019-05-04T20:58:39Z" data-provider="getTestData" finished-at="2019-05-04T20:58:40Z">
          <params>
            <param index="0">
              <value>
                <![CDATA[nagesh]]>
              </value>
            </param>
            <param index="1">
              <value>
                <![CDATA[test]]>
              </value>
            </param>
          </params>
          <reporter-output>
          </reporter-output>
        </test-method> <!-- validateInvalidLogins -->
        <test-method status="PASS" signature="tearDown()[pri:0, instance:com.crm.qa.testcases.LoginPageTest@627551fb]" name="tearDown" is-config="true" duration-ms="683" started-at="2019-05-04T20:58:40Z" finished-at="2019-05-04T20:58:41Z">
          <reporter-output>
          </reporter-output>
        </test-method> <!-- tearDown -->
        <test-method status="PASS" signature="setUp()[pri:0, instance:com.crm.qa.testcases.LoginPageTest@627551fb]" name="setUp" is-config="true" duration-ms="7357" started-at="2019-05-04T20:58:41Z" finished-at="2019-05-04T20:58:48Z">
          <reporter-output>
          </reporter-output>
        </test-method> <!-- setUp -->
        <test-method status="PASS" signature="validateInvalidLogins(java.lang.String, java.lang.String)[pri:3, instance:com.crm.qa.testcases.LoginPageTest@627551fb]" name="validateInvalidLogins" duration-ms="836" started-at="2019-05-04T20:58:48Z" data-provider="getTestData" finished-at="2019-05-04T20:58:49Z">
          <params>
            <param index="0">
              <value>
                <![CDATA[Suresh]]>
              </value>
            </param>
            <param index="1">
              <value>
                <![CDATA[ewqewqe]]>
              </value>
            </param>
          </params>
          <reporter-output>
          </reporter-output>
        </test-method> <!-- validateInvalidLogins -->
        <test-method status="PASS" signature="tearDown()[pri:0, instance:com.crm.qa.testcases.LoginPageTest@627551fb]" name="tearDown" is-config="true" duration-ms="693" started-at="2019-05-04T20:58:49Z" finished-at="2019-05-04T20:58:50Z">
          <reporter-output>
          </reporter-output>
        </test-method> <!-- tearDown -->
        <test-method status="PASS" signature="setUp()[pri:0, instance:com.crm.qa.testcases.LoginPageTest@627551fb]" name="setUp" is-config="true" duration-ms="7125" started-at="2019-05-04T20:58:50Z" finished-at="2019-05-04T20:58:57Z">
          <reporter-output>
          </reporter-output>
        </test-method> <!-- setUp -->
        <test-method status="PASS" signature="validateInvalidLogins(java.lang.String, java.lang.String)[pri:3, instance:com.crm.qa.testcases.LoginPageTest@627551fb]" name="validateInvalidLogins" duration-ms="795" started-at="2019-05-04T20:58:57Z" data-provider="getTestData" finished-at="2019-05-04T20:58:57Z">
          <params>
            <param index="0">
              <value>
                <![CDATA[Kamal]]>
              </value>
            </param>
            <param index="1">
              <value>
                <![CDATA[ginga]]>
              </value>
            </param>
          </params>
          <reporter-output>
          </reporter-output>
        </test-method> <!-- validateInvalidLogins -->
        <test-method status="PASS" signature="tearDown()[pri:0, instance:com.crm.qa.testcases.LoginPageTest@627551fb]" name="tearDown" is-config="true" duration-ms="688" started-at="2019-05-04T20:58:57Z" finished-at="2019-05-04T20:58:58Z">
          <reporter-output>
          </reporter-output>
        </test-method> <!-- tearDown -->
        <test-method status="PASS" signature="setUp()[pri:0, instance:com.crm.qa.testcases.LoginPageTest@627551fb]" name="setUp" is-config="true" duration-ms="6979" started-at="2019-05-04T20:58:58Z" finished-at="2019-05-04T20:59:05Z">
          <reporter-output>
          </reporter-output>
        </test-method> <!-- setUp -->
        <test-method status="PASS" signature="validateInvalidLogins(java.lang.String, java.lang.String)[pri:3, instance:com.crm.qa.testcases.LoginPageTest@627551fb]" name="validateInvalidLogins" duration-ms="816" started-at="2019-05-04T20:59:05Z" data-provider="getTestData" finished-at="2019-05-04T20:59:06Z">
          <params>
            <param index="0">
              <value>
                <![CDATA[Diana]]>
              </value>
            </param>
            <param index="1">
              <value>
                <![CDATA[porer]]>
              </value>
            </param>
          </params>
          <reporter-output>
          </reporter-output>
        </test-method> <!-- validateInvalidLogins -->
        <test-method status="PASS" signature="tearDown()[pri:0, instance:com.crm.qa.testcases.LoginPageTest@627551fb]" name="tearDown" is-config="true" duration-ms="690" started-at="2019-05-04T20:59:06Z" finished-at="2019-05-04T20:59:07Z">
          <reporter-output>
          </reporter-output>
        </test-method> <!-- tearDown -->
      </class> <!-- com.crm.qa.testcases.LoginPageTest -->
      <class name="com.crm.qa.testcases.RetryLogicTest">
        <test-method status="SKIP" signature="Test1()[pri:0, instance:com.crm.qa.testcases.RetryLogicTest@1f36e637]" name="Test1" duration-ms="11" started-at="2019-05-04T20:57:55Z" finished-at="2019-05-04T20:57:55Z">
          <exception class="java.lang.AssertionError">
            <message>
              <![CDATA[expected [true] but found [false]]]>
            </message>
            <full-stacktrace>
              <![CDATA[java.lang.AssertionError: expected [true] but found [false]
	at org.testng.Assert.fail(Assert.java:93)
	at org.testng.Assert.failNotEquals(Assert.java:512)
	at org.testng.Assert.assertEqualsImpl(Assert.java:134)
	at org.testng.Assert.assertEquals(Assert.java:115)
	at org.testng.Assert.assertEquals(Assert.java:304)
	at org.testng.Assert.assertEquals(Assert.java:314)
	at com.crm.qa.testcases.RetryLogicTest.Test1(RetryLogicTest.java:10)
	at sun.reflect.NativeMethodAccessorImpl.invoke0(Native Method)
	at sun.reflect.NativeMethodAccessorImpl.invoke(Unknown Source)
	at sun.reflect.DelegatingMethodAccessorImpl.invoke(Unknown Source)
	at java.lang.reflect.Method.invoke(Unknown Source)
	at org.testng.internal.MethodInvocationHelper.invokeMethod(MethodInvocationHelper.java:108)
	at org.testng.internal.Invoker.invokeMethod(Invoker.java:661)
	at org.testng.internal.Invoker.invokeTestMethod(Invoker.java:869)
	at org.testng.internal.Invoker.invokeTestMethods(Invoker.java:1193)
	at org.testng.internal.TestMethodWorker.invokeTestMethods(TestMethodWorker.java:126)
	at org.testng.internal.TestMethodWorker.run(TestMethodWorker.java:109)
	at org.testng.TestRunner.privateRun(TestRunner.java:744)
	at org.testng.TestRunner.run(TestRunner.java:602)
	at org.testng.SuiteRunner.runTest(SuiteRunner.java:380)
	at org.testng.SuiteRunner.runSequentially(SuiteRunner.java:375)
	at org.testng.SuiteRunner.privateRun(SuiteRunner.java:340)
	at org.testng.SuiteRunner.run(SuiteRunner.java:289)
	at org.testng.SuiteRunnerWorker.runSuite(SuiteRunnerWorker.java:52)
	at org.testng.SuiteRunnerWorker.run(SuiteRunnerWorker.java:86)
	at org.testng.TestNG.runSuitesSequentially(TestNG.java:1301)
	at org.testng.TestNG.runSuitesLocally(TestNG.java:1226)
	at org.testng.TestNG.runSuites(TestNG.java:1144)
	at org.testng.TestNG.run(TestNG.java:1115)
	at org.testng.remote.AbstractRemoteTestNG.run(AbstractRemoteTestNG.java:115)
	at org.testng.remote.RemoteTestNG.initAndRun(RemoteTestNG.java:251)
	at org.testng.remote.RemoteTestNG.main(RemoteTestNG.java:77)
]]>
            </full-stacktrace>
          </exception> <!-- java.lang.AssertionError -->
          <reporter-output>
          </reporter-output>
        </test-method> <!-- Test1 -->
        <test-method status="SKIP" signature="Test1()[pri:0, instance:com.crm.qa.testcases.RetryLogicTest@1f36e637]" name="Test1" duration-ms="1" started-at="2019-05-04T20:57:55Z" finished-at="2019-05-04T20:57:55Z">
          <exception class="java.lang.AssertionError">
            <message>
              <![CDATA[expected [true] but found [false]]]>
            </message>
            <full-stacktrace>
              <![CDATA[java.lang.AssertionError: expected [true] but found [false]
	at org.testng.Assert.fail(Assert.java:93)
	at org.testng.Assert.failNotEquals(Assert.java:512)
	at org.testng.Assert.assertEqualsImpl(Assert.java:134)
	at org.testng.Assert.assertEquals(Assert.java:115)
	at org.testng.Assert.assertEquals(Assert.java:304)
	at org.testng.Assert.assertEquals(Assert.java:314)
	at com.crm.qa.testcases.RetryLogicTest.Test1(RetryLogicTest.java:10)
	at sun.reflect.NativeMethodAccessorImpl.invoke0(Native Method)
	at sun.reflect.NativeMethodAccessorImpl.invoke(Unknown Source)
	at sun.reflect.DelegatingMethodAccessorImpl.invoke(Unknown Source)
	at java.lang.reflect.Method.invoke(Unknown Source)
	at org.testng.internal.MethodInvocationHelper.invokeMethod(MethodInvocationHelper.java:108)
	at org.testng.internal.Invoker.invokeMethod(Invoker.java:661)
	at org.testng.internal.Invoker.retryFailed(Invoker.java:1014)
	at org.testng.internal.Invoker.invokeTestMethods(Invoker.java:1215)
	at org.testng.internal.TestMethodWorker.invokeTestMethods(TestMethodWorker.java:126)
	at org.testng.internal.TestMethodWorker.run(TestMethodWorker.java:109)
	at org.testng.TestRunner.privateRun(TestRunner.java:744)
	at org.testng.TestRunner.run(TestRunner.java:602)
	at org.testng.SuiteRunner.runTest(SuiteRunner.java:380)
	at org.testng.SuiteRunner.runSequentially(SuiteRunner.java:375)
	at org.testng.SuiteRunner.privateRun(SuiteRunner.java:340)
	at org.testng.SuiteRunner.run(SuiteRunner.java:289)
	at org.testng.SuiteRunnerWorker.runSuite(SuiteRunnerWorker.java:52)
	at org.testng.SuiteRunnerWorker.run(SuiteRunnerWorker.java:86)
	at org.testng.TestNG.runSuitesSequentially(TestNG.java:1301)
	at org.testng.TestNG.runSuitesLocally(TestNG.java:1226)
	at org.testng.TestNG.runSuites(TestNG.java:1144)
	at org.testng.TestNG.run(TestNG.java:1115)
	at org.testng.remote.AbstractRemoteTestNG.run(AbstractRemoteTestNG.java:115)
	at org.testng.remote.RemoteTestNG.initAndRun(RemoteTestNG.java:251)
	at org.testng.remote.RemoteTestNG.main(RemoteTestNG.java:77)
]]>
            </full-stacktrace>
          </exception> <!-- java.lang.AssertionError -->
          <reporter-output>
          </reporter-output>
        </test-method> <!-- Test1 -->
        <test-method status="SKIP" signature="Test1()[pri:0, instance:com.crm.qa.testcases.RetryLogicTest@1f36e637]" name="Test1" duration-ms="1" started-at="2019-05-04T20:57:55Z" finished-at="2019-05-04T20:57:55Z">
          <exception class="java.lang.AssertionError">
            <message>
              <![CDATA[expected [true] but found [false]]]>
            </message>
            <full-stacktrace>
              <![CDATA[java.lang.AssertionError: expected [true] but found [false]
	at org.testng.Assert.fail(Assert.java:93)
	at org.testng.Assert.failNotEquals(Assert.java:512)
	at org.testng.Assert.assertEqualsImpl(Assert.java:134)
	at org.testng.Assert.assertEquals(Assert.java:115)
	at org.testng.Assert.assertEquals(Assert.java:304)
	at org.testng.Assert.assertEquals(Assert.java:314)
	at com.crm.qa.testcases.RetryLogicTest.Test1(RetryLogicTest.java:10)
	at sun.reflect.NativeMethodAccessorImpl.invoke0(Native Method)
	at sun.reflect.NativeMethodAccessorImpl.invoke(Unknown Source)
	at sun.reflect.DelegatingMethodAccessorImpl.invoke(Unknown Source)
	at java.lang.reflect.Method.invoke(Unknown Source)
	at org.testng.internal.MethodInvocationHelper.invokeMethod(MethodInvocationHelper.java:108)
	at org.testng.internal.Invoker.invokeMethod(Invoker.java:661)
	at org.testng.internal.Invoker.retryFailed(Invoker.java:1014)
	at org.testng.internal.Invoker.invokeTestMethods(Invoker.java:1215)
	at org.testng.internal.TestMethodWorker.invokeTestMethods(TestMethodWorker.java:126)
	at org.testng.internal.TestMethodWorker.run(TestMethodWorker.java:109)
	at org.testng.TestRunner.privateRun(TestRunner.java:744)
	at org.testng.TestRunner.run(TestRunner.java:602)
	at org.testng.SuiteRunner.runTest(SuiteRunner.java:380)
	at org.testng.SuiteRunner.runSequentially(SuiteRunner.java:375)
	at org.testng.SuiteRunner.privateRun(SuiteRunner.java:340)
	at org.testng.SuiteRunner.run(SuiteRunner.java:289)
	at org.testng.SuiteRunnerWorker.runSuite(SuiteRunnerWorker.java:52)
	at org.testng.SuiteRunnerWorker.run(SuiteRunnerWorker.java:86)
	at org.testng.TestNG.runSuitesSequentially(TestNG.java:1301)
	at org.testng.TestNG.runSuitesLocally(TestNG.java:1226)
	at org.testng.TestNG.runSuites(TestNG.java:1144)
	at org.testng.TestNG.run(TestNG.java:1115)
	at org.testng.remote.AbstractRemoteTestNG.run(AbstractRemoteTestNG.java:115)
	at org.testng.remote.RemoteTestNG.initAndRun(RemoteTestNG.java:251)
	at org.testng.remote.RemoteTestNG.main(RemoteTestNG.java:77)
]]>
            </full-stacktrace>
          </exception> <!-- java.lang.AssertionError -->
          <reporter-output>
          </reporter-output>
        </test-method> <!-- Test1 -->
        <test-method status="FAIL" signature="Test1()[pri:0, instance:com.crm.qa.testcases.RetryLogicTest@1f36e637]" name="Test1" duration-ms="1" started-at="2019-05-04T20:57:55Z" finished-at="2019-05-04T20:57:55Z">
          <exception class="java.lang.AssertionError">
            <message>
              <![CDATA[expected [true] but found [false]]]>
            </message>
            <full-stacktrace>
              <![CDATA[java.lang.AssertionError: expected [true] but found [false]
	at org.testng.Assert.fail(Assert.java:93)
	at org.testng.Assert.failNotEquals(Assert.java:512)
	at org.testng.Assert.assertEqualsImpl(Assert.java:134)
	at org.testng.Assert.assertEquals(Assert.java:115)
	at org.testng.Assert.assertEquals(Assert.java:304)
	at org.testng.Assert.assertEquals(Assert.java:314)
	at com.crm.qa.testcases.RetryLogicTest.Test1(RetryLogicTest.java:10)
	at sun.reflect.NativeMethodAccessorImpl.invoke0(Native Method)
	at sun.reflect.NativeMethodAccessorImpl.invoke(Unknown Source)
	at sun.reflect.DelegatingMethodAccessorImpl.invoke(Unknown Source)
	at java.lang.reflect.Method.invoke(Unknown Source)
	at org.testng.internal.MethodInvocationHelper.invokeMethod(MethodInvocationHelper.java:108)
	at org.testng.internal.Invoker.invokeMethod(Invoker.java:661)
	at org.testng.internal.Invoker.retryFailed(Invoker.java:1014)
	at org.testng.internal.Invoker.invokeTestMethods(Invoker.java:1215)
	at org.testng.internal.TestMethodWorker.invokeTestMethods(TestMethodWorker.java:126)
	at org.testng.internal.TestMethodWorker.run(TestMethodWorker.java:109)
	at org.testng.TestRunner.privateRun(TestRunner.java:744)
	at org.testng.TestRunner.run(TestRunner.java:602)
	at org.testng.SuiteRunner.runTest(SuiteRunner.java:380)
	at org.testng.SuiteRunner.runSequentially(SuiteRunner.java:375)
	at org.testng.SuiteRunner.privateRun(SuiteRunner.java:340)
	at org.testng.SuiteRunner.run(SuiteRunner.java:289)
	at org.testng.SuiteRunnerWorker.runSuite(SuiteRunnerWorker.java:52)
	at org.testng.SuiteRunnerWorker.run(SuiteRunnerWorker.java:86)
	at org.testng.TestNG.runSuitesSequentially(TestNG.java:1301)
	at org.testng.TestNG.runSuitesLocally(TestNG.java:1226)
	at org.testng.TestNG.runSuites(TestNG.java:1144)
	at org.testng.TestNG.run(TestNG.java:1115)
	at org.testng.remote.AbstractRemoteTestNG.run(AbstractRemoteTestNG.java:115)
	at org.testng.remote.RemoteTestNG.initAndRun(RemoteTestNG.java:251)
	at org.testng.remote.RemoteTestNG.main(RemoteTestNG.java:77)
]]>
            </full-stacktrace>
          </exception> <!-- java.lang.AssertionError -->
          <reporter-output>
          </reporter-output>
        </test-method> <!-- Test1 -->
        <test-method status="SKIP" signature="Test2()[pri:0, instance:com.crm.qa.testcases.RetryLogicTest@1f36e637]" name="Test2" duration-ms="0" started-at="2019-05-04T20:57:55Z" finished-at="2019-05-04T20:57:55Z">
          <exception class="java.lang.AssertionError">
            <message>
              <![CDATA[expected [true] but found [false]]]>
            </message>
            <full-stacktrace>
              <![CDATA[java.lang.AssertionError: expected [true] but found [false]
	at org.testng.Assert.fail(Assert.java:93)
	at org.testng.Assert.failNotEquals(Assert.java:512)
	at org.testng.Assert.assertEqualsImpl(Assert.java:134)
	at org.testng.Assert.assertEquals(Assert.java:115)
	at org.testng.Assert.assertEquals(Assert.java:304)
	at org.testng.Assert.assertEquals(Assert.java:314)
	at com.crm.qa.testcases.RetryLogicTest.Test2(RetryLogicTest.java:15)
	at sun.reflect.NativeMethodAccessorImpl.invoke0(Native Method)
	at sun.reflect.NativeMethodAccessorImpl.invoke(Unknown Source)
	at sun.reflect.DelegatingMethodAccessorImpl.invoke(Unknown Source)
	at java.lang.reflect.Method.invoke(Unknown Source)
	at org.testng.internal.MethodInvocationHelper.invokeMethod(MethodInvocationHelper.java:108)
	at org.testng.internal.Invoker.invokeMethod(Invoker.java:661)
	at org.testng.internal.Invoker.invokeTestMethod(Invoker.java:869)
	at org.testng.internal.Invoker.invokeTestMethods(Invoker.java:1193)
	at org.testng.internal.TestMethodWorker.invokeTestMethods(TestMethodWorker.java:126)
	at org.testng.internal.TestMethodWorker.run(TestMethodWorker.java:109)
	at org.testng.TestRunner.privateRun(TestRunner.java:744)
	at org.testng.TestRunner.run(TestRunner.java:602)
	at org.testng.SuiteRunner.runTest(SuiteRunner.java:380)
	at org.testng.SuiteRunner.runSequentially(SuiteRunner.java:375)
	at org.testng.SuiteRunner.privateRun(SuiteRunner.java:340)
	at org.testng.SuiteRunner.run(SuiteRunner.java:289)
	at org.testng.SuiteRunnerWorker.runSuite(SuiteRunnerWorker.java:52)
	at org.testng.SuiteRunnerWorker.run(SuiteRunnerWorker.java:86)
	at org.testng.TestNG.runSuitesSequentially(TestNG.java:1301)
	at org.testng.TestNG.runSuitesLocally(TestNG.java:1226)
	at org.testng.TestNG.runSuites(TestNG.java:1144)
	at org.testng.TestNG.run(TestNG.java:1115)
	at org.testng.remote.AbstractRemoteTestNG.run(AbstractRemoteTestNG.java:115)
	at org.testng.remote.RemoteTestNG.initAndRun(RemoteTestNG.java:251)
	at org.testng.remote.RemoteTestNG.main(RemoteTestNG.java:77)
]]>
            </full-stacktrace>
          </exception> <!-- java.lang.AssertionError -->
          <reporter-output>
          </reporter-output>
        </test-method> <!-- Test2 -->
        <test-method status="SKIP" signature="Test2()[pri:0, instance:com.crm.qa.testcases.RetryLogicTest@1f36e637]" name="Test2" duration-ms="1" started-at="2019-05-04T20:57:55Z" finished-at="2019-05-04T20:57:55Z">
          <exception class="java.lang.AssertionError">
            <message>
              <![CDATA[expected [true] but found [false]]]>
            </message>
            <full-stacktrace>
              <![CDATA[java.lang.AssertionError: expected [true] but found [false]
	at org.testng.Assert.fail(Assert.java:93)
	at org.testng.Assert.failNotEquals(Assert.java:512)
	at org.testng.Assert.assertEqualsImpl(Assert.java:134)
	at org.testng.Assert.assertEquals(Assert.java:115)
	at org.testng.Assert.assertEquals(Assert.java:304)
	at org.testng.Assert.assertEquals(Assert.java:314)
	at com.crm.qa.testcases.RetryLogicTest.Test2(RetryLogicTest.java:15)
	at sun.reflect.NativeMethodAccessorImpl.invoke0(Native Method)
	at sun.reflect.NativeMethodAccessorImpl.invoke(Unknown Source)
	at sun.reflect.DelegatingMethodAccessorImpl.invoke(Unknown Source)
	at java.lang.reflect.Method.invoke(Unknown Source)
	at org.testng.internal.MethodInvocationHelper.invokeMethod(MethodInvocationHelper.java:108)
	at org.testng.internal.Invoker.invokeMethod(Invoker.java:661)
	at org.testng.internal.Invoker.retryFailed(Invoker.java:1014)
	at org.testng.internal.Invoker.invokeTestMethods(Invoker.java:1215)
	at org.testng.internal.TestMethodWorker.invokeTestMethods(TestMethodWorker.java:126)
	at org.testng.internal.TestMethodWorker.run(TestMethodWorker.java:109)
	at org.testng.TestRunner.privateRun(TestRunner.java:744)
	at org.testng.TestRunner.run(TestRunner.java:602)
	at org.testng.SuiteRunner.runTest(SuiteRunner.java:380)
	at org.testng.SuiteRunner.runSequentially(SuiteRunner.java:375)
	at org.testng.SuiteRunner.privateRun(SuiteRunner.java:340)
	at org.testng.SuiteRunner.run(SuiteRunner.java:289)
	at org.testng.SuiteRunnerWorker.runSuite(SuiteRunnerWorker.java:52)
	at org.testng.SuiteRunnerWorker.run(SuiteRunnerWorker.java:86)
	at org.testng.TestNG.runSuitesSequentially(TestNG.java:1301)
	at org.testng.TestNG.runSuitesLocally(TestNG.java:1226)
	at org.testng.TestNG.runSuites(TestNG.java:1144)
	at org.testng.TestNG.run(TestNG.java:1115)
	at org.testng.remote.AbstractRemoteTestNG.run(AbstractRemoteTestNG.java:115)
	at org.testng.remote.RemoteTestNG.initAndRun(RemoteTestNG.java:251)
	at org.testng.remote.RemoteTestNG.main(RemoteTestNG.java:77)
]]>
            </full-stacktrace>
          </exception> <!-- java.lang.AssertionError -->
          <reporter-output>
          </reporter-output>
        </test-method> <!-- Test2 -->
        <test-method status="SKIP" signature="Test2()[pri:0, instance:com.crm.qa.testcases.RetryLogicTest@1f36e637]" name="Test2" duration-ms="1" started-at="2019-05-04T20:57:55Z" finished-at="2019-05-04T20:57:55Z">
          <exception class="java.lang.AssertionError">
            <message>
              <![CDATA[expected [true] but found [false]]]>
            </message>
            <full-stacktrace>
              <![CDATA[java.lang.AssertionError: expected [true] but found [false]
	at org.testng.Assert.fail(Assert.java:93)
	at org.testng.Assert.failNotEquals(Assert.java:512)
	at org.testng.Assert.assertEqualsImpl(Assert.java:134)
	at org.testng.Assert.assertEquals(Assert.java:115)
	at org.testng.Assert.assertEquals(Assert.java:304)
	at org.testng.Assert.assertEquals(Assert.java:314)
	at com.crm.qa.testcases.RetryLogicTest.Test2(RetryLogicTest.java:15)
	at sun.reflect.NativeMethodAccessorImpl.invoke0(Native Method)
	at sun.reflect.NativeMethodAccessorImpl.invoke(Unknown Source)
	at sun.reflect.DelegatingMethodAccessorImpl.invoke(Unknown Source)
	at java.lang.reflect.Method.invoke(Unknown Source)
	at org.testng.internal.MethodInvocationHelper.invokeMethod(MethodInvocationHelper.java:108)
	at org.testng.internal.Invoker.invokeMethod(Invoker.java:661)
	at org.testng.internal.Invoker.retryFailed(Invoker.java:1014)
	at org.testng.internal.Invoker.invokeTestMethods(Invoker.java:1215)
	at org.testng.internal.TestMethodWorker.invokeTestMethods(TestMethodWorker.java:126)
	at org.testng.internal.TestMethodWorker.run(TestMethodWorker.java:109)
	at org.testng.TestRunner.privateRun(TestRunner.java:744)
	at org.testng.TestRunner.run(TestRunner.java:602)
	at org.testng.SuiteRunner.runTest(SuiteRunner.java:380)
	at org.testng.SuiteRunner.runSequentially(SuiteRunner.java:375)
	at org.testng.SuiteRunner.privateRun(SuiteRunner.java:340)
	at org.testng.SuiteRunner.run(SuiteRunner.java:289)
	at org.testng.SuiteRunnerWorker.runSuite(SuiteRunnerWorker.java:52)
	at org.testng.SuiteRunnerWorker.run(SuiteRunnerWorker.java:86)
	at org.testng.TestNG.runSuitesSequentially(TestNG.java:1301)
	at org.testng.TestNG.runSuitesLocally(TestNG.java:1226)
	at org.testng.TestNG.runSuites(TestNG.java:1144)
	at org.testng.TestNG.run(TestNG.java:1115)
	at org.testng.remote.AbstractRemoteTestNG.run(AbstractRemoteTestNG.java:115)
	at org.testng.remote.RemoteTestNG.initAndRun(RemoteTestNG.java:251)
	at org.testng.remote.RemoteTestNG.main(RemoteTestNG.java:77)
]]>
            </full-stacktrace>
          </exception> <!-- java.lang.AssertionError -->
          <reporter-output>
          </reporter-output>
        </test-method> <!-- Test2 -->
        <test-method status="FAIL" signature="Test2()[pri:0, instance:com.crm.qa.testcases.RetryLogicTest@1f36e637]" name="Test2" duration-ms="1" started-at="2019-05-04T20:57:55Z" finished-at="2019-05-04T20:57:55Z">
          <exception class="java.lang.AssertionError">
            <message>
              <![CDATA[expected [true] but found [false]]]>
            </message>
            <full-stacktrace>
              <![CDATA[java.lang.AssertionError: expected [true] but found [false]
	at org.testng.Assert.fail(Assert.java:93)
	at org.testng.Assert.failNotEquals(Assert.java:512)
	at org.testng.Assert.assertEqualsImpl(Assert.java:134)
	at org.testng.Assert.assertEquals(Assert.java:115)
	at org.testng.Assert.assertEquals(Assert.java:304)
	at org.testng.Assert.assertEquals(Assert.java:314)
	at com.crm.qa.testcases.RetryLogicTest.Test2(RetryLogicTest.java:15)
	at sun.reflect.NativeMethodAccessorImpl.invoke0(Native Method)
	at sun.reflect.NativeMethodAccessorImpl.invoke(Unknown Source)
	at sun.reflect.DelegatingMethodAccessorImpl.invoke(Unknown Source)
	at java.lang.reflect.Method.invoke(Unknown Source)
	at org.testng.internal.MethodInvocationHelper.invokeMethod(MethodInvocationHelper.java:108)
	at org.testng.internal.Invoker.invokeMethod(Invoker.java:661)
	at org.testng.internal.Invoker.retryFailed(Invoker.java:1014)
	at org.testng.internal.Invoker.invokeTestMethods(Invoker.java:1215)
	at org.testng.internal.TestMethodWorker.invokeTestMethods(TestMethodWorker.java:126)
	at org.testng.internal.TestMethodWorker.run(TestMethodWorker.java:109)
	at org.testng.TestRunner.privateRun(TestRunner.java:744)
	at org.testng.TestRunner.run(TestRunner.java:602)
	at org.testng.SuiteRunner.runTest(SuiteRunner.java:380)
	at org.testng.SuiteRunner.runSequentially(SuiteRunner.java:375)
	at org.testng.SuiteRunner.privateRun(SuiteRunner.java:340)
	at org.testng.SuiteRunner.run(SuiteRunner.java:289)
	at org.testng.SuiteRunnerWorker.runSuite(SuiteRunnerWorker.java:52)
	at org.testng.SuiteRunnerWorker.run(SuiteRunnerWorker.java:86)
	at org.testng.TestNG.runSuitesSequentially(TestNG.java:1301)
	at org.testng.TestNG.runSuitesLocally(TestNG.java:1226)
	at org.testng.TestNG.runSuites(TestNG.java:1144)
	at org.testng.TestNG.run(TestNG.java:1115)
	at org.testng.remote.AbstractRemoteTestNG.run(AbstractRemoteTestNG.java:115)
	at org.testng.remote.RemoteTestNG.initAndRun(RemoteTestNG.java:251)
	at org.testng.remote.RemoteTestNG.main(RemoteTestNG.java:77)
]]>
            </full-stacktrace>
          </exception> <!-- java.lang.AssertionError -->
          <reporter-output>
          </reporter-output>
        </test-method> <!-- Test2 -->
      </class> <!-- com.crm.qa.testcases.RetryLogicTest -->
    </test> <!-- Free CRM App Test Cases -->
  </suite> <!-- FREE CRM Application Test Automation Test Suite -->
</testng-results>
